<?xml version="1.0" ?>
<!-- =================================================================================== -->
<!-- |    This document was autogenerated by xacro from warthog_description/urdf/warthog.urdf.xacro | -->
<!-- |    EDITING THIS FILE BY HAND IS NOT RECOMMENDED                                 | -->
<!-- =================================================================================== -->
<robot name="warthog">
  <material name="dark_grey">
    <color rgba="0.2 0.2 0.2 1.0"/>
  </material>
  <material name="light_grey">
    <color rgba="0.4 0.4 0.4 1.0"/>
  </material>
  <material name="yellow">
    <color rgba="0.95 0.816 0.082 1.0"/>
  </material>
  <material name="black">
    <color rgba="0.15 0.15 0.15 1.0"/>
  </material>
  <material name="white">
    <color rgba="0.9 0.9 0.9 1.0"/>
  </material>
  <material name="red">
    <color rgba="0.9 0.0 0.0 1.0"/>
  </material>
  <link name="front_left_wheel_link">
    <inertial>
      <origin rpy="0 0 0" xyz="0 0 0"/>
      <mass value="15"/>
      <inertia ixx="0.41562499999999997" ixy="0" ixz="0" iyy="0.6749999999999999" iyz="0" izz="0.41562499999999997"/>
    </inertial>
    <visual>
      <origin rpy="0 0 1.5707963267948966" xyz="0 0 0"/>
      <geometry>
        <mesh filename="/home/rahulreghunath/Desktop/first/warthog_descriptions/meshes/wheel.stl"/>
      </geometry>
      <material name="dark_grey"/>
    </visual>
    <collision>
      <origin rpy="1.5707963267948966 0 0" xyz="0 0 0"/>
      <geometry>
        <cylinder length="0.25" radius="0.3"/>
      </geometry>
    </collision>
  </link>
  <joint name="front_left_wheel_joint" type="continuous">
    <parent link="left_diff_unit_link"/>
    <child link="front_left_wheel_link"/>
    <origin rpy="0 0 0" xyz="0.457367 0.0 -0.012977"/>
    <axis xyz="0 1 0"/>
  </joint>
  <gazebo reference="front_left_wheel_link">
    <selfCollide>false</selfCollide>
    <mu1>0.5</mu1>
    <mu2>0.5</mu2>
    <kp value="10000000.0"/>
    <kd value="1.0"/>
    <fdir1 value="1 0 0"/>
    <material>Gazebo/DarkGrey</material>
  </gazebo>
  <transmission name="front_left_wheel_trans">
    <type>transmission_interface/SimpleTransmission</type>
    <joint name="front_left_wheel_joint">
      <hardwareInterface>hardware_interface/VelocityJointInterface</hardwareInterface>
    </joint>
    <actuator name="front_left_actuator">
      <hardwareInterface>hardware_interface/VelocityJointInterface</hardwareInterface>
      <mechanicalReduction>1</mechanicalReduction>
    </actuator>
  </transmission>
  <link name="front_right_wheel_link">
    <inertial>
      <origin rpy="0 0 0" xyz="0 0 0"/>
      <mass value="15"/>
      <inertia ixx="0.41562499999999997" ixy="0" ixz="0" iyy="0.6749999999999999" iyz="0" izz="0.41562499999999997"/>
    </inertial>
    <visual>
      <origin rpy="0 0 1.5707963267948966" xyz="0 0 0"/>
      <geometry>
        <mesh filename="/home/rahulreghunath/Desktop/first/warthog_descriptions/meshes/wheel.stl"/>
      </geometry>
      <material name="dark_grey"/>
    </visual>
    <collision>
      <origin rpy="1.5707963267948966 0 0" xyz="0 0 0"/>
      <geometry>
        <cylinder length="0.25" radius="0.3"/>
      </geometry>
    </collision>
  </link>
  <joint name="front_right_wheel_joint" type="continuous">
    <parent link="right_diff_unit_link"/>
    <child link="front_right_wheel_link"/>
    <origin rpy="0 0 0" xyz="0.457367 -0.0 -0.012977"/>
    <axis xyz="0 1 0"/>
  </joint>
  <gazebo reference="front_right_wheel_link">
    <selfCollide>false</selfCollide>
    <mu1>0.5</mu1>
    <mu2>0.5</mu2>
    <kp value="10000000.0"/>
    <kd value="1.0"/>
    <fdir1 value="1 0 0"/>
    <material>Gazebo/DarkGrey</material>
  </gazebo>
  <transmission name="front_right_wheel_trans">
    <type>transmission_interface/SimpleTransmission</type>
    <joint name="front_right_wheel_joint">
      <hardwareInterface>hardware_interface/VelocityJointInterface</hardwareInterface>
    </joint>
    <actuator name="front_right_actuator">
      <hardwareInterface>hardware_interface/VelocityJointInterface</hardwareInterface>
      <mechanicalReduction>1</mechanicalReduction>
    </actuator>
  </transmission>
  <link name="rear_left_wheel_link">
    <inertial>
      <origin rpy="0 0 0" xyz="0 0 0"/>
      <mass value="15"/>
      <inertia ixx="0.41562499999999997" ixy="0" ixz="0" iyy="0.6749999999999999" iyz="0" izz="0.41562499999999997"/>
    </inertial>
    <visual>
      <origin rpy="0 0 1.5707963267948966" xyz="0 0 0"/>
      <geometry>
        <mesh filename="/home/rahulreghunath/Desktop/first/warthog_descriptions/meshes/wheel.stl"/>
      </geometry>
      <material name="dark_grey"/>
    </visual>
    <collision>
      <origin rpy="1.5707963267948966 0 0" xyz="0 0 0"/>
      <geometry>
        <cylinder length="0.25" radius="0.3"/>
      </geometry>
    </collision>
  </link>
  <joint name="rear_left_wheel_joint" type="continuous">
    <parent link="left_diff_unit_link"/>
    <child link="rear_left_wheel_link"/>
    <origin rpy="0 0 0" xyz="-0.457367 0.0 -0.012977"/>
    <axis xyz="0 1 0"/>
  </joint>
  <gazebo reference="rear_left_wheel_link">
    <selfCollide>false</selfCollide>
    <mu1>0.5</mu1>
    <mu2>0.5</mu2>
    <kp value="10000000.0"/>
    <kd value="1.0"/>
    <fdir1 value="1 0 0"/>
    <material>Gazebo/DarkGrey</material>
  </gazebo>
  <transmission name="rear_left_wheel_trans">
    <type>transmission_interface/SimpleTransmission</type>
    <joint name="rear_left_wheel_joint">
      <hardwareInterface>hardware_interface/VelocityJointInterface</hardwareInterface>
    </joint>
    <actuator name="rear_left_actuator">
      <hardwareInterface>hardware_interface/VelocityJointInterface</hardwareInterface>
      <mechanicalReduction>1</mechanicalReduction>
    </actuator>
  </transmission>
  <link name="rear_right_wheel_link">
    <inertial>
      <origin rpy="0 0 0" xyz="0 0 0"/>
      <mass value="15"/>
      <inertia ixx="0.41562499999999997" ixy="0" ixz="0" iyy="0.6749999999999999" iyz="0" izz="0.41562499999999997"/>
    </inertial>
    <visual>
      <origin rpy="0 0 1.5707963267948966" xyz="0 0 0"/>
      <geometry>
        <mesh filename="/home/rahulreghunath/Desktop/first/warthog_descriptions/meshes/wheel.stl"/>
      </geometry>
      <material name="dark_grey"/>
    </visual>
    <collision>
      <origin rpy="1.5707963267948966 0 0" xyz="0 0 0"/>
      <geometry>
        <cylinder length="0.25" radius="0.3"/>
      </geometry>
    </collision>
  </link>
  <joint name="rear_right_wheel_joint" type="continuous">
    <parent link="right_diff_unit_link"/>
    <child link="rear_right_wheel_link"/>
    <origin rpy="0 0 0" xyz="-0.457367 -0.0 -0.012977"/>
    <axis xyz="0 1 0"/>
  </joint>
  <gazebo reference="rear_right_wheel_link">
    <selfCollide>false</selfCollide>
    <mu1>0.5</mu1>
    <mu2>0.5</mu2>
    <kp value="10000000.0"/>
    <kd value="1.0"/>
    <fdir1 value="1 0 0"/>
    <material>Gazebo/DarkGrey</material>
  </gazebo>
  <transmission name="rear_right_wheel_trans">
    <type>transmission_interface/SimpleTransmission</type>
    <joint name="rear_right_wheel_joint">
      <hardwareInterface>hardware_interface/VelocityJointInterface</hardwareInterface>
    </joint>
    <actuator name="rear_right_actuator">
      <hardwareInterface>hardware_interface/VelocityJointInterface</hardwareInterface>
      <mechanicalReduction>1</mechanicalReduction>
    </actuator>
  </transmission>
  <link name="left_diff_unit_link">
    <inertial>
      <origin rpy="0 0 0" xyz="0 -0.05 0.197"/>
      <mass value="50"/>
      <inertia ixx="1.980416666666667" ixy="0" ixz="0" iyy="9.135416666666668" iyz="0" izz="9.135416666666668"/>
    </inertial>
    <visual>
      <origin rpy="0 0 1.5707963267948966" xyz="0 0 0"/>
      <geometry>
        <mesh filename="/home/rahulreghunath/Desktop/first/warthog_descriptions/meshes/rocker.stl"/>
      </geometry>
      <material name="black">
        <color rgba="0.15 0.15 0.15 1.0"/>
      </material>
    </visual>
    <visual>
      <origin rpy="0 0 1.5707963267948966" xyz="0 0 0"/>
      <geometry>
        <mesh filename="/home/rahulreghunath/Desktop/first/warthog_descriptions/meshes/fenders.stl"/>
      </geometry>
      <material name="yellow">
        <color rgba="0.95 0.816 0.082 1.0"/>
      </material>
    </visual>
    <collision>
      <origin rpy="0 0 1.5707963267948966" xyz="0 0 0"/>
      <geometry>
        <mesh filename="/home/rahulreghunath/Desktop/first/warthog_descriptions/meshes/fenders_collision.stl"/>
      </geometry>
    </collision>
    <collision>
      <origin rpy="0 0 1.5707963267948966" xyz="0.0 -0.02 0.52"/>
      <geometry>
        <box size="0.28 0.95 0.024"/>
      </geometry>
    </collision>
  </link>
  <joint name="left_diff_unit_joint" type="revolute">
    <limit effort="100" lower="-0.4" upper="0.4" velocity="1"/>
    <parent link="chassis_link"/>
    <child link="left_diff_unit_link"/>
    <origin rpy="0 0 0" xyz="0.0 0.56821 0.0"/>
    <axis xyz="0 1 0"/>
    <dynamics damping="100" friction="0.5"/>
  </joint>
  <link name="left_diff_unit_buttons_link">
    <visual>
      <geometry>
        <mesh filename="/home/rahulreghunath/Desktop/first/warthog_descriptions/meshes/buttons.stl"/>
      </geometry>
      <material name="red">
        <color rgba="0.9 0.0 0.0 1.0"/>
      </material>
    </visual>
    <collision>
      <origin rpy="0 0 0" xyz="0.0395 0.4315 0.520"/>
      <geometry>
        <cylinder length="0.014" radius="0.0205"/>
        <material name="red">
          <color rgba="0.9 0.0 0.0 1.0"/>
        </material>
      </geometry>
    </collision>
    <collision>
      <origin rpy="0 0 0" xyz="0.0395 -0.4315 0.520"/>
      <geometry>
        <cylinder length="0.014" radius="0.0205"/>
        <material name="red">
          <color rgba="0.9 0.0 0.0 1.0"/>
        </material>
      </geometry>
    </collision>
  </link>
  <joint name="left_diff_unit_buttons" type="fixed">
    <origin rpy="0 0 1.5707963267948966" xyz="0 0 0"/>
    <parent link="left_diff_unit_link"/>
    <child link="left_diff_unit_buttons_link"/>
  </joint>
  <!-- Wi-Fi and Controller Antenna -->
  <link name="left_diff_unit_antenna_link">
    <visual>
      <material name="light_grey"/>
      <geometry>
        <mesh filename="/home/rahulreghunath/Desktop/first/warthog_descriptions/meshes/antenna_left.stl"/>
      </geometry>
    </visual>
    <collision>
      <origin rpy="0 0 0" xyz="-0.096 0.431 0.6635"/>
      <geometry>
        <cylinder length="0.301" radius="0.01697"/>
      </geometry>
      <material name="light_grey"/>
    </collision>
  </link>
  <joint name="left_diff_unit_antenna_joint" type="fixed">
    <origin rpy="0 0 1.5707963267948966" xyz="0 0 0"/>
    <parent link="left_diff_unit_link"/>
    <child link="left_diff_unit_antenna_link"/>
  </joint>
  <link name="left_diff_unit_headlight_link">
    <visual>
      <origin rpy="0 0 0" xyz="0 -0.029 0"/>
      <geometry>
        <mesh filename="/home/rahulreghunath/Desktop/first/warthog_descriptions/meshes/light.stl"/>
      </geometry>
      <material name="white">
        <color rgba="0.9 0.9 0.9 1.0"/>
      </material>
    </visual>
    <collision>
      <origin rpy="0 0 0" xyz="0 -0.022 0"/>
      <geometry>
        <mesh filename="/home/rahulreghunath/Desktop/first/warthog_descriptions/meshes/light_collision.stl"/>
      </geometry>
      <material name="white">
        <color rgba="0.9 0.9 0.9 1.0"/>
      </material>
    </collision>
  </link>
  <joint name="left_diff_unit_headlight_joint" type="fixed">
    <parent link="left_diff_unit_link"/>
    <child link="left_diff_unit_headlight_link"/>
    <origin rpy="0 0 0" xyz="0 0 0"/>
  </joint>
  <gazebo reference="left_diff_unit_headlight_link">
    <visual>
      <material>
        <ambient>0.9 0.9 0.9 1</ambient>
        <diffuse>0.9 0.9 0.9 1</diffuse>
        <specular>0.9 0.9 0.9 1</specular>
        <emissive>0.9 0.9 0.9 1</emissive>
      </material>
    </visual>
  </gazebo>
  <link name="left_diff_unit_taillight_link">
    <visual>
      <origin rpy="0 0 3.141592653589793" xyz="0 -0.029 0"/>
      <geometry>
        <mesh filename="/home/rahulreghunath/Desktop/first/warthog_descriptions/meshes/light.stl"/>
      </geometry>
      <material name="red">
        <color rgba="0.9 0.0 0.0 1.0"/>
      </material>
    </visual>
    <collision>
      <origin rpy="0 0 3.141592653589793" xyz="0 -0.022 0"/>
      <geometry>
        <mesh filename="/home/rahulreghunath/Desktop/first/warthog_descriptions/meshes/light_collision.stl"/>
      </geometry>
      <material name="red">
        <color rgba="0.9 0.0 0.0 1.0"/>
      </material>
    </collision>
  </link>
  <joint name="left_diff_unit_taillight_joint" type="fixed">
    <parent link="left_diff_unit_link"/>
    <child link="left_diff_unit_taillight_link"/>
    <origin rpy="0 0 0" xyz="0 0 0"/>
  </joint>
  <gazebo reference="left_diff_unit_taillight_link">
    <visual>
      <material>
        <ambient>0.9 0 0 1</ambient>
        <diffuse>0.9 0 0 1</diffuse>
        <specular>0.9 0 0 1</specular>
        <emissive>0.9 0 0 1</emissive>
      </material>
    </visual>
  </gazebo>
  <gazebo reference="left_diff_unit_link">
    <selfCollide>false</selfCollide>
    <visual>
      <material>
        <ambient>0.95 0.816 0.082 1.0</ambient>
        <diffuse>0.95 0.816 0.082 1.0</diffuse>
        <specular>0.1 0.1 0.1 1</specular>
        <emissive>0 0 0 0</emissive>
      </material>
    </visual>
  </gazebo>
  <link name="right_diff_unit_link">
    <inertial>
      <origin rpy="0 0 0" xyz="0 0.05 0.197"/>
      <mass value="50"/>
      <inertia ixx="1.980416666666667" ixy="0" ixz="0" iyy="9.135416666666668" iyz="0" izz="9.135416666666668"/>
    </inertial>
    <visual>
      <origin rpy="0 0 -1.5707963267948966" xyz="0 0 0"/>
      <geometry>
        <mesh filename="/home/rahulreghunath/Desktop/first/warthog_descriptions/meshes/rocker.stl"/>
      </geometry>
      <material name="black">
        <color rgba="0.15 0.15 0.15 1.0"/>
      </material>
    </visual>
    <visual>
      <origin rpy="0 0 -1.5707963267948966" xyz="0 0 0"/>
      <geometry>
        <mesh filename="/home/rahulreghunath/Desktop/first/warthog_descriptions/meshes/fenders.stl"/>
      </geometry>
      <material name="yellow">
        <color rgba="0.95 0.816 0.082 1.0"/>
      </material>
    </visual>
    <collision>
      <origin rpy="0 0 -1.5707963267948966" xyz="0 0 0"/>
      <geometry>
        <mesh filename="/home/rahulreghunath/Desktop/first/warthog_descriptions/meshes/fenders_collision.stl"/>
      </geometry>
    </collision>
    <collision>
      <origin rpy="0 0 -1.5707963267948966" xyz="0.0 0.02 0.52"/>
      <geometry>
        <box size="0.28 0.95 0.024"/>
      </geometry>
    </collision>
  </link>
  <joint name="right_diff_unit_joint" type="revolute">
    <limit effort="100" lower="-0.4" upper="0.4" velocity="1"/>
    <parent link="chassis_link"/>
    <child link="right_diff_unit_link"/>
    <origin rpy="0 0 0" xyz="0.0 -0.56821 0.0"/>
    <axis xyz="0 1 0"/>
    <dynamics damping="100" friction="0.5"/>
  </joint>
  <link name="right_diff_unit_buttons_link">
    <visual>
      <geometry>
        <mesh filename="/home/rahulreghunath/Desktop/first/warthog_descriptions/meshes/buttons.stl"/>
      </geometry>
      <material name="red">
        <color rgba="0.9 0.0 0.0 1.0"/>
      </material>
    </visual>
    <collision>
      <origin rpy="0 0 0" xyz="0.0395 0.4315 0.520"/>
      <geometry>
        <cylinder length="0.014" radius="0.0205"/>
        <material name="red">
          <color rgba="0.9 0.0 0.0 1.0"/>
        </material>
      </geometry>
    </collision>
    <collision>
      <origin rpy="0 0 0" xyz="0.0395 -0.4315 0.520"/>
      <geometry>
        <cylinder length="0.014" radius="0.0205"/>
        <material name="red">
          <color rgba="0.9 0.0 0.0 1.0"/>
        </material>
      </geometry>
    </collision>
  </link>
  <joint name="right_diff_unit_buttons" type="fixed">
    <origin rpy="0 0 -1.5707963267948966" xyz="0 0 0"/>
    <parent link="right_diff_unit_link"/>
    <child link="right_diff_unit_buttons_link"/>
  </joint>
  <!-- Wi-Fi and Controller Antenna -->
  <link name="right_diff_unit_antenna_link">
    <visual>
      <material name="light_grey"/>
      <geometry>
        <mesh filename="/home/rahulreghunath/Desktop/first/warthog_descriptions/meshes/antenna_right.stl"/>
      </geometry>
    </visual>
    <collision>
      <origin rpy="0 0 0" xyz="-0.096 -0.431 0.6635"/>
      <geometry>
        <cylinder length="0.301" radius="0.01697"/>
      </geometry>
      <material name="light_grey"/>
    </collision>
  </link>
  <joint name="right_diff_unit_antenna_joint" type="fixed">
    <origin rpy="0 0 -1.5707963267948966" xyz="0 0 0"/>
    <parent link="right_diff_unit_link"/>
    <child link="right_diff_unit_antenna_link"/>
  </joint>
  <link name="right_diff_unit_estop_antenna_link">
    <visual>
      <material name="light_grey"/>
      <geometry>
        <mesh filename="/home/rahulreghunath/Desktop/first/warthog_descriptions/meshes/antenna_estop.stl"/>
      </geometry>
    </visual>
    <collision>
      <material name="light_grey"/>
      <origin rpy="0 0 0" xyz="-0.096 0.4315 0.572"/>
      <geometry>
        <cylinder length="0.118" radius="0.0103"/>
      </geometry>
    </collision>
  </link>
  <joint name="right_diff_unit_estop_antenna_joint" type="fixed">
    <origin rpy="0 0 -1.5707963267948966" xyz="0 0 0"/>
    <parent link="right_diff_unit_link"/>
    <child link="right_diff_unit_estop_antenna_link"/>
  </joint>
  <link name="right_diff_unit_headlight_link">
    <visual>
      <origin rpy="0 0 0" xyz="0 0.029 0"/>
      <geometry>
        <mesh filename="/home/rahulreghunath/Desktop/first/warthog_descriptions/meshes/light.stl"/>
      </geometry>
      <material name="white">
        <color rgba="0.9 0.9 0.9 1.0"/>
      </material>
    </visual>
    <collision>
      <origin rpy="0 0 0" xyz="0 0.022 0"/>
      <geometry>
        <mesh filename="/home/rahulreghunath/Desktop/first/warthog_descriptions/meshes/light_collision.stl"/>
      </geometry>
      <material name="white">
        <color rgba="0.9 0.9 0.9 1.0"/>
      </material>
    </collision>
  </link>
  <joint name="right_diff_unit_headlight_joint" type="fixed">
    <parent link="right_diff_unit_link"/>
    <child link="right_diff_unit_headlight_link"/>
    <origin rpy="0 0 0" xyz="0 0 0"/>
  </joint>
  <gazebo reference="right_diff_unit_headlight_link">
    <visual>
      <material>
        <ambient>0.9 0.9 0.9 1</ambient>
        <diffuse>0.9 0.9 0.9 1</diffuse>
        <specular>0.9 0.9 0.9 1</specular>
        <emissive>0.9 0.9 0.9 1</emissive>
      </material>
    </visual>
  </gazebo>
  <link name="right_diff_unit_taillight_link">
    <visual>
      <origin rpy="0 0 -3.141592653589793" xyz="0 0.029 0"/>
      <geometry>
        <mesh filename="/home/rahulreghunath/Desktop/first/warthog_descriptions/meshes/light.stl"/>
      </geometry>
      <material name="red">
        <color rgba="0.9 0.0 0.0 1.0"/>
      </material>
    </visual>
    <collision>
      <origin rpy="0 0 -3.141592653589793" xyz="0 0.022 0"/>
      <geometry>
        <mesh filename="/home/rahulreghunath/Desktop/first/warthog_descriptions/meshes/light_collision.stl"/>
      </geometry>
      <material name="red">
        <color rgba="0.9 0.0 0.0 1.0"/>
      </material>
    </collision>
  </link>
  <joint name="right_diff_unit_taillight_joint" type="fixed">
    <parent link="right_diff_unit_link"/>
    <child link="right_diff_unit_taillight_link"/>
    <origin rpy="0 0 0" xyz="0 0 0"/>
  </joint>
  <gazebo reference="right_diff_unit_taillight_link">
    <visual>
      <material>
        <ambient>0.9 0 0 1</ambient>
        <diffuse>0.9 0 0 1</diffuse>
        <specular>0.9 0 0 1</specular>
        <emissive>0.9 0 0 1</emissive>
      </material>
    </visual>
  </gazebo>
  <gazebo reference="right_diff_unit_link">
    <selfCollide>false</selfCollide>
    <visual>
      <material>
        <ambient>0.95 0.816 0.082 1.0</ambient>
        <diffuse>0.95 0.816 0.082 1.0</diffuse>
        <specular>0.1 0.1 0.1 1</specular>
        <emissive>0 0 0 0</emissive>
      </material>
    </visual>
  </gazebo>
  <link name="base_link"/>
  <joint name="base_link_joint" type="fixed">
    <origin rpy="0 0 0" xyz="0 0 0.025"/>
    <parent link="base_link"/>
    <child link="chassis_link"/>
  </joint>
  <link name="chassis_link">
    <inertial>
      <origin rpy="0 0 0" xyz="0 0 0"/>
      <mass value="100"/>
      <inertia ixx="4.833333333333333" ixy="0" ixz="0" iyy="15.937500000000002" iyz="0" izz="15.937500000000002"/>
    </inertial>
    <visual>
      <origin rpy="0 0 0" xyz="0 0 0"/>
      <geometry>
        <mesh filename="/home/rahulreghunath/Desktop/first/warthog_descriptions/meshes/chassis.stl"/>
      </geometry>
      <material name="black">
        <color rgba="0.15 0.15 0.15 1.0"/>
      </material>
    </visual>
    <visual>
      <origin rpy="0 0 0" xyz="0 0 0"/>
      <geometry>
        <mesh filename="/home/rahulreghunath/Desktop/first/warthog_descriptions/meshes/e_stop.stl"/>
      </geometry>
      <material name="red">
        <color rgba="0.9 0.0 0.0 1.0"/>
      </material>
    </visual>
    <collision>
      <origin rpy="0 0 0" xyz="0 0 0"/>
      <geometry>
        <mesh filename="/home/rahulreghunath/Desktop/first/warthog_descriptions/meshes/chassis_collision.stl"/>
      </geometry>
    </collision>
  </link>
  <link name="top_chassis_link"/>
  <joint name="top_link_joint" type="fixed">
    <origin rpy="0 0 0" xyz="0 0 0.27218"/>
    <parent link="chassis_link"/>
    <child link="top_chassis_link"/>
  </joint>
  <!-- This link is purely to complete the visual look -->
  <link name="diff_link">
    <visual>
      <origin rpy="0 0 0" xyz="0 0 0"/>
      <geometry>
        <mesh filename="/home/rahulreghunath/Desktop/first/warthog_descriptions/meshes/diff_link.stl"/>
      </geometry>
      <material name="light_grey"/>
    </visual>
    <visual>
      <origin rpy="0 0 0" xyz="0 0 0"/>
      <geometry>
        <mesh filename="/home/rahulreghunath/Desktop/first/warthog_descriptions/meshes/susp_link.stl"/>
      </geometry>
      <material name="light_grey"/>
    </visual>
    <visual>
      <origin rpy="0 0 0" xyz="0 0 0"/>
      <geometry>
        <mesh filename="/home/rahulreghunath/Desktop/first/warthog_descriptions/meshes/susp_link.stl"/>
      </geometry>
      <material name="light_grey"/>
    </visual>
  </link>
  <joint name="diff_link_joint" type="fixed">
    <parent link="chassis_link"/>
    <child link="diff_link"/>
    <origin rpy="0 0 0" xyz="-0.5826 0 0.24979"/>
  </joint>
  <link name="imu_link"/>
  <joint name="imu_link_joint" type="fixed">
    <origin rpy="0 0 0" xyz="0 0 0"/>
    <parent link="chassis_link"/>
    <child link="imu_link"/>
  </joint>
  
  <!--
    As you add to this URDF, please be aware that both the robot and
    simulation include it. You must retain compatibility with all of
    the following launch files:

    warthog_viz/launch/view_model.launch
    warthog_gazebo/launch/warthog_world.launch
    warthog_base/launch/base.launch
  -->
  <!-- This file is a placeholder which is included by default from
       warthog.urdf.xacro. If a robot is being customized and requires
       additional URDF, set the WARTHOG_URDF_EXTRAS environment variable
       to the full path of the file you would like included. -->
  <!-- This file is a placeholder which is included by default from
       warthog.urdf.xacro. If a robot is being customized and requires
       additional URDF, set the WARTHOG_URDF_EXTRAS environment variable
       to the full path of the file you would like included. -->
</robot>
